#VRML_SIM R2025a utf8

EXTERNPROTO "https://raw.githubusercontent.com/cyberbotics/webots/R2025a/projects/objects/backgrounds/protos/TexturedBackground.proto"
EXTERNPROTO "https://raw.githubusercontent.com/cyberbotics/webots/R2025a/projects/objects/backgrounds/protos/TexturedBackgroundLight.proto"
EXTERNPROTO "https://raw.githubusercontent.com/cyberbotics/webots/R2025a/projects/objects/floors/protos/RectangleArena.proto"
EXTERNPROTO "https://raw.githubusercontent.com/cyberbotics/webots/R2025a/projects/objects/factory/containers/protos/WoodenBox.proto"

WorldInfo {
}
Viewpoint {
  orientation 0.3890445344671587 0.11211055075205863 -0.9143716829666708 2.6263102357049046
  position 0.8638195727042731 0.4220038148894461 0.9931599274569644
}
TexturedBackground {
}
TexturedBackgroundLight {
}
RectangleArena {
  translation 0.01 1.10113e-13 0.07
  rotation 1 0 0 4.692820414042842e-06
  floorTileSize 0.25 0.25
}
WoodenBox {
  translation -0.06 0.31 0.13
  rotation -1 0 0 -5.307179586466759e-06
  size 0.125 0.125 0.125
}
WoodenBox {
  translation -0.05 -0.0599982 0.13
  rotation 0.9999934699443532 -0.0036138716983296877 -9.589734506671008e-09 5.30716e-06
  name "wooden box(1)"
  size 0.125 0.125 0.125
}
WoodenBox {
  translation -0.3 -0.309998 0.13
  rotation 0.9999934699443532 -0.0036138716983296877 -9.589734506671008e-09 5.30716e-06
  name "wooden box(4)"
  size 0.125 0.125 0.125
}
WoodenBox {
  translation 0.32 0.43 0.13
  rotation 1 0 0 5.30716e-06
  name "wooden box(2)"
  size 0.125 0.125 0.125
}
WoodenBox {
  translation 0.2 -0.31 0.13
  rotation -1 0 0 -5.307179586466759e-06
  name "wooden box(3)"
  size 0.125 0.125 0.125
}
Robot {
  translation 0.1947691372559994 0.003986473014046988 0.10357660819327703
  rotation -0.00029816082420322396 0.0001443568531013038 -0.9999999451306093 1.4125646517863448
  children [
    DistanceSensor {
      translation -0.0291417 -0.072453 0.00082838
      rotation 0.196121519737426 0 0.9805795987556963 -1.9634996938995748
      children [
        DEF sensor Shape {
          appearance PBRAppearance {
            baseColor 0 0 0
            metalness 0
          }
          geometry Box {
            size 0.01 0.01 0.01
          }
        }
      ]
      name "sensor_izquierdo"
      boundingObject USE sensor
      physics Physics {
      }
    }
    DistanceSensor {
      translation 0.029316 -0.0724118 -5.195e-05
      rotation 0.2642143586240745 0 0.9644639820630259 -1.3090003061004252
      children [
        DEF sensor Shape {
          appearance PBRAppearance {
            baseColor 0 0 0
            metalness 0
          }
          geometry Box {
            size 0.01 0.01 0.01
          }
        }
      ]
      name "sensor_derecho"
      boundingObject USE sensor
      physics Physics {
      }
    }
    HingeJoint {
      jointParameters HingeJointParameters {
        position 94.99981735362348
        anchor 0.0603874 -0.0430283 -0.00377462
      }
      device [
        RotationalMotor {
          name "rueda_1"
        }
      ]
      endPoint Solid {
        translation 0.06038740346580034 -0.04302655087051897 -0.003776497579748055
        rotation -0.344711915702258 0.8731259153016322 0.34470977822157334 4.577122377265446
        children [
          DEF rueda Shape {
            appearance PBRAppearance {
              baseColor 1 1 0
              metalness 0
            }
            geometry Cylinder {
              height 0.02
              radius 0.03
            }
          }
        ]
        boundingObject USE rueda
        physics DEF fisica_rueda Physics {
        }
        linearVelocity -0.029624736369173094 -0.004727024104206644 6.719551442165623e-08
        angularVelocity 0.1575853379517285 -0.9875072085753427 9.981358210453162e-05
      }
    }
    HingeJoint {
      jointParameters HingeJointParameters {
        position 11.999048139544257
        anchor -0.0596486 0.0469436 -0.00371474
      }
      device [
        RotationalMotor {
          name "rueda_4"
        }
      ]
      endPoint Solid {
        translation -0.05964860047388331 0.046943595911098895 -0.0037147424420976155
        rotation -0.26951508178541583 -0.9245112038698106 0.2695193028511948 1.6492061775442592
        children [
          DEF rueda Shape {
            appearance PBRAppearance {
              baseColor 1 1 0
              metalness 0
            }
            geometry Cylinder {
              height 0.02
              radius 0.03
            }
          }
        ]
        name "solid(1)"
        boundingObject USE rueda
        physics DEF fisica_rueda Physics {
        }
        linearVelocity -0.02962550123386701 -0.004728065165223159 4.102160718859883e-08
        angularVelocity 0.15758534505074615 -0.9875072631768416 9.98045236130943e-05
      }
    }
    HingeJoint {
      jointParameters HingeJointParameters {
        position 94.9998248060223
        anchor 0.0603514 0.0469436 -0.00371583
      }
      device [
        RotationalMotor {
          name "rueda_3"
        }
      ]
      endPoint Solid {
        translation 0.06035140149287713 0.046945026693243 -0.003717354612434264
        rotation -0.3447153982795111 0.8731233744778882 0.3447127313131085 4.577120554588181
        children [
          DEF rueda Shape {
            appearance PBRAppearance {
              baseColor 1 1 0
              metalness 0
            }
            geometry Cylinder {
              height 0.02
              radius 0.03
            }
          }
        ]
        name "solid(3)"
        boundingObject USE rueda
        physics DEF fisica_rueda Physics {
        }
        linearVelocity -0.029624986887734944 -0.00472798309489104 -7.998078653680918e-08
        angularVelocity 0.15758534033340194 -0.9875072323582024 9.980447494580786e-05
      }
    }
    HingeJoint {
      jointParameters HingeJointParameters {
        position 11.999043822707065
        anchor -0.0596578 -0.0430533 -0.00375408
      }
      device [
        RotationalMotor {
          name "rueda_2"
        }
      ]
      endPoint Solid {
        translation -0.0596578005182389 -0.04305329862372612 -0.0037540795918128093
        rotation -0.269516363750251 -0.9245103419480177 0.2695209774804206 1.6492091265707343
        children [
          DEF rueda Shape {
            appearance PBRAppearance {
              baseColor 1 1 0
              metalness 0
            }
            geometry Cylinder {
              height 0.02
              radius 0.03
            }
          }
        ]
        name "solid(2)"
        boundingObject USE rueda
        physics DEF fisica_rueda Physics {
        }
        linearVelocity -0.029625645105095924 -0.004727169021125452 -1.1686864895193092e-07
        angularVelocity 0.1575853464561891 -0.987507263004211 9.981369560003787e-05
      }
    }
    DEF body Shape {
      appearance PBRAppearance {
        baseColor 1 0 1
      }
      geometry Box {
        size 0.1 0.15 0.04
      }
    }
  ]
  boundingObject USE body
  physics Physics {
  }
  controller "obstaculo"
  linearVelocity -0.029626072104457862 -0.00472772514752264 -8.023878372185928e-07
  angularVelocity 1.2897523372600384e-05 1.82383694653045e-07 -9.035265233846685e-06
}
